Workbook

Sheet Modern Transect Elev Summary
A1: Orthometric height (m)
A2: Grover | B2: Oscar | C2: BertErnie | D2: BigBird | E2: CookieMonster
A3: =Grover!E7 -> -0.38813 | B3: =Oscar!E7 -> 0.1331 | C3: =BertErnie!E7 -> -0.03395 | D3: ='BigBird (Fangyi)'!E7 -> 0.11408 | E3: =CookieMonster!E7 -> 0.07071
A4: =Grover!E8 -> -0.14813 | B4: =Oscar!E8 -> 0.2881 | C4: =BertErnie!E8 -> 0.23605 | D4: ='BigBird (Fangyi)'!E8 -> 0.28408 | E4: =CookieMonster!E8 -> 0.18571
A5: =Grover!E9 -> -0.02813 | B5: =Oscar!E9 -> 0.3131 | C5: =BertErnie!E9 -> 0.33605 | D5: ='BigBird (Fangyi)'!E9 -> 0.35408 | E5: =CookieMonster!E9 -> 0.30071
A6: =Grover!E10 -> 0.16187 | B6: =Oscar!E10 -> 0.3031 | C6: =BertErnie!E10 -> 0.35605 | D6: ='BigBird (Fangyi)'!E10 -> 0.37408 | E6: =CookieMonster!E10 -> 0.39571
A7: =Grover!E11 -> 0.17687 | B7: =Oscar!E11 -> 0.3031 | C7: =BertErnie!E11 -> 0.35605 | D7: ='BigBird (Fangyi)'!E11 -> 0.42408 | E7: =CookieMonster!E12 -> 0.44071
A8: =Grover!E12 -> 0.20187 | B8: =Oscar!E12 -> 0.2631 | C8: =BertErnie!E12 -> 0.38605 | D8: ='BigBird (Fangyi)'!E12 -> 0.46408 | E8: =CookieMonster!E13 -> 0.44571
A9: =Grover!E13 -> 0.22187 | B9: =Oscar!E14 -> 0.2431 | C9: =BertErnie!E13 -> 0.51605 | D9: ='BigBird (Fangyi)'!E13 -> 0.46408 | E9: =CookieMonster!E14 -> 0.44571
A10: =Grover!E14 -> 0.21687 | B10: =Oscar!E15 -> 0.2931 | C10: =BertErnie!E14 -> 0.68605 | D10: ='BigBird (Fangyi)'!E14 -> 0.44908 | E10: =CookieMonster!E16 -> 0.44071
A11: =Grover!E16 -> 0.20687 | B11: =Oscar!E16 -> 0.1931 | C11: =BertErnie!E16 -> 0.48605 | D11: ='BigBird (Fangyi)'!E16 -> 0.44408 | E11: =CookieMonster!E17 -> 0.46071
A12: =Grover!E18 -> 0.19187 | B12: =Oscar!E17 -> 0.1431 | C12: =BertErnie!E17 -> 0.47605 | D12: ='BigBird (Fangyi)'!E17 -> 0.44908 | E12: =CookieMonster!E18 -> 0.50571
A13: =Grover!E19 -> 0.19687 | B13: =Oscar!E18 -> 0.1031 | C13: =BertErnie!E18 -> 0.48605 | D13: ='BigBird (Fangyi)'!E18 -> 0.42908 | E13: =CookieMonster!E19 -> 0.46571
A14: =Grover!E20 -> 0.19687 | B14: =Oscar!E19 -> 0.1131 | C14: =BertErnie!E19 -> 0.47605 | D14: ='BigBird (Fangyi)'!E20 -> 0.39908 | E14: =CookieMonster!E20 -> 0.39071
A15: =Grover!E21 -> 0.16187 | B15: =Oscar!E20 -> 0.2731 | C15: =BertErnie!E20 -> 0.46605 | D15: ='BigBird (Fangyi)'!E21 -> 0.38908 | E15: =CookieMonster!E21 -> 0.34071
A16: =Grover!E22 -> 0.26187 | B16: =Oscar!E21 -> 0.2531 | C16: =BertErnie!E22 -> 0.43605 | D16: ='BigBird (Fangyi)'!E22 -> 0.21908 | E16: =CookieMonster!E22 -> 0.15071
A17: =Grover!E24 -> 0.28187 | B17: =Oscar!E22 -> 0.2531 | C17: =BertErnie!E23 -> 0.42605 | D17: ='BigBird (Fangyi)'!E23 -> 0.17908 | E17: =CookieMonster!E23 -> -0.09929
A18: =Grover!E25 -> 0.32187 | B18: =Oscar!E23 -> 0.2431 | C18: =BertErnie!E25 -> 0.42105 | D18: ='BigBird (Fangyi)'!E25 -> 0.16908 | E18: =CookieMonster!E24 -> -0.19929
A19: =Grover!E26 -> 0.30187 | B19: =Oscar!E24 -> 0.2131 | C19: =BertErnie!E26 -> 0.36605 | D19: ='BigBird (Fangyi)'!E26 -> 0.12908
A20: =Grover!E27 -> 0.25187 | B20: =Oscar!E25 -> 0.2331 | C20: =BertErnie!E27 -> 0.33605 | D20: ='BigBird (Fangyi)'!E27 -> 0.17908
A21: =Grover!E29 -> -0.35313 | B21: =Oscar!E26 -> 0.0331 | C21: =BertErnie!E28 -> 0.30605 | D21: ='BigBird (Fangyi)'!E28 -> 0.16908
A22: =Grover!E30 -> -0.70813 | B22: =Oscar!E27 -> 0.0431 | C22: =BertErnie!E29 -> 0.25605 | D22: ='BigBird (Fangyi)'!E29 -> 0.22908
A23: =Grover!E31 -> -0.16313 | B23: =Oscar!E28 -> 0.0131 | C23: =BertErnie!E30 -> 0.21605 | D23: ='BigBird (Fangyi)'!E31 -> 0.35908
A24: =Grover!E32 -> 0.01687 | B24: =Oscar!E30 -> 0.3481 | C24: =BertErnie!E31 -> 0.17605 | D24: ='BigBird (Fangyi)'!E32 -> 0.38908
A25: =Grover!E33 -> 0.03687 | B25: =Oscar!E31 -> 0.4531 | C25: =BertErnie!E32 -> 0.20605 | D25: ='BigBird (Fangyi)'!E33 -> 0.38908
A26: =Grover!E34 -> 0.15687 | B26: =Oscar!E33 -> 0.4231 | C26: =BertErnie!E34 -> 0.23605 | D26: ='BigBird (Fangyi)'!E35 -> 0.39908
A27: =Grover!E35 -> 0.20687 | B27: =Oscar!E35 -> 0.4081 | C27: =BertErnie!E35 -> 0.40605 | D27: ='BigBird (Fangyi)'!E36 -> 0.41908
A28: =Grover!E36 -> 0.24187 | B28: =Oscar!E37 -> 0.3981 | D28: ='BigBird (Fangyi)'!E38 -> 0.44908
A29: =Grover!E37 -> 0.25687 | B29: =Oscar!E38 -> 0.3881 | D29: ='BigBird (Fangyi)'!E39 -> 0.46908
A30: =Grover!E39 -> 0.28687 | B30: =Oscar!E40 -> 0.4031 | D30: ='BigBird (Fangyi)'!E41 -> 0.49908
A31: =Grover!E40 -> 0.25187 | B31: =Oscar!E41 -> 0.4131 | D31: ='BigBird (Fangyi)'!E42 -> 0.40908
A32: =Grover!E41 -> -0.13813 | B32: =Oscar!E43 -> 0.4031 | D32: ='BigBird (Fangyi)'!E43 -> 0.39908
A33: =Grover!E42 -> -0.22813 | B33: =Oscar!E45 -> 0.4231 | D33: ='BigBird (Fangyi)'!E45 -> 0.38908
A34: =Grover!E43 -> -0.67813 | B34: =Oscar!E46 -> 0.4131 | D34: ='BigBird (Fangyi)'!E46 -> 0.34908
B35: =Oscar!E48 -> 0.3681 | D35: ='BigBird (Fangyi)'!E47 -> 0.29908
B36: =Oscar!E49 -> 0.3431 | D36: ='BigBird (Fangyi)'!E48 -> 0.21908
B37: =Oscar!E50 -> 0.2981 | D37: ='BigBird (Fangyi)'!E49 -> 0.17908
B38: =Oscar!E51 -> 0.0031 | D38: ='BigBird (Fangyi)'!E50 -> -0.08092
B39: =Oscar!E52 -> 0.4181

Sheet Indicative meanings
A1: Orthometric height (m)
A2: Grover | B2: Oscar | C2: BertErnie | D2: BigBird | E2: CookieMonster
A3: =Grover!H12 -> -0.14813 | B3: =Oscar!L11 -> 0.1331 | C3: =BertErnie!G14 -> 0.38605 | D3: ='BigBird (Fangyi)'!L11 -> 0.28408 | E3: =CookieMonster!N14 -> 0.44071
A4: =Grover!H13 -> -0.02813 | B4: =Oscar!L12 -> 0.2881 | C4: =BertErnie!G15 -> 0.51605 | D4: ='BigBird (Fangyi)'!L12 -> 0.35408 | E4: =CookieMonster!N15 -> 0.44571
A5: =Grover!H14 -> 0.16187 | B5: =Oscar!L13 -> 0.3131 | C5: =BertErnie!G16 -> 0.48605 | D5: ='BigBird (Fangyi)'!L13 -> 0.37408 | E5: =CookieMonster!N16 -> 0.44571
A6: =Grover!H15 -> 0.17687 | B6: =Oscar!L14 -> 0.3031 | C6: =BertErnie!G17 -> 0.47605 | D6: ='BigBird (Fangyi)'!L14 -> 0.42408 | E6: =CookieMonster!N17 -> 0.44071
A7: =Grover!H16 -> 0.20187 | B7: =Oscar!L15 -> 0.3031 | C7: =BertErnie!G18 -> 0.48605 | D7: ='BigBird (Fangyi)'!L15 -> 0.46408 | E7: =CookieMonster!N18 -> 0.46071
A8: =Grover!H17 -> 0.22187 | B8: =Oscar!L16 -> 0.2931 | C8: =BertErnie!G19 -> 0.47605 | D8: ='BigBird (Fangyi)'!L16 -> 0.46408 | E8: =CookieMonster!N19 -> 0.50571
A9: =Grover!H18 -> 0.21687 | B9: =Oscar!L17 -> 0.4531 | C9: =BertErnie!G20 -> 0.46605 | D9: ='BigBird (Fangyi)'!L17 -> 0.44408 | E9: =CookieMonster!N20 -> 0.46571
A10: =Grover!H19 -> 0.20687 | B10: =Oscar!L18 -> 0.4231 | C10: =BertErnie!G21 -> 0.43605 | D10: ='BigBird (Fangyi)'!L18 -> 0.44908 | E10: =CookieMonster!N21 -> 0.39071
A11: =Grover!H20 -> 0.19187 | B11: =Oscar!L19 -> 0.4081 | C11: =BertErnie!G22 -> 0.42605 | D11: ='BigBird (Fangyi)'!L19 -> 0.42908
A12: =Grover!H21 -> 0.19687 | B12: =Oscar!L20 -> 0.3881 | C12: =BertErnie!G23 -> 0.42105 | D12: ='BigBird (Fangyi)'!L20 -> 0.39908
A13: =Grover!H22 -> 0.19687 | B13: =Oscar!L21 -> 0.4031 | C13: =BertErnie!G24 -> 0.36605 | D13: ='BigBird (Fangyi)'!L21 -> 0.38908
A14: =Grover!H23 -> 0.16187 | B14: =Oscar!L22 -> 0.4131 | C14: =BertErnie!G25 -> 0.33605 | D14: ='BigBird (Fangyi)'!L22 -> 0.35908
A15: =Grover!H24 -> 0.26187 | B15: =Oscar!L23 -> 0.4231 | C15: =BertErnie!G26 -> 0.30605 | D15: ='BigBird (Fangyi)'!L23 -> 0.44908
A16: =Grover!H25 -> 0.28187 | B16: =Oscar!L24 -> 0.4131 | C16: =BertErnie!G27 -> 0.25605 | D16: ='BigBird (Fangyi)'!L24 -> 0.46908
A17: =Grover!H26 -> 0.32187 | B17: =Oscar!L25 -> 0.3681 | C17: =BertErnie!G28 -> 0.21605 | D17: ='BigBird (Fangyi)'!L25 -> 0.49908
A18: =Grover!H27 -> 0.30187 | B18: =Oscar!L26 -> 0.3431 | D18: ='BigBird (Fangyi)'!L26 -> 0.40908
A19: =Grover!H28 -> 0.25187 | B19: =Oscar!L27 -> 0.2981 | D19: ='BigBird (Fangyi)'!L27 -> 0.39908
A20: =Grover!H29 -> 0.20687 | D20: ='BigBird (Fangyi)'!L28 -> 0.38908
A21: =Grover!H30 -> 0.24187 | D21: ='BigBird (Fangyi)'!L29 -> 0.34908
A22: =Grover!H31 -> 0.25687 | D22: ='BigBird (Fangyi)'!L30 -> 0.29908
A23: =Grover!H32 -> 0.25187 | D23: ='BigBird (Fangyi)'!L31 -> 0.21908

Sheet Grover
A1: Site: | B1: GR/19 | J1: Base Station | K1: Ellipsoid height | L1: Geoid Height | M1: Orthometric height
A2: Date: | B2: 5/11/19 (afternoon) | K2: -4.462 | L2: -4.61887 | M2: 0.15687
A3: What: | B3: Leveling GR environmental zones and core
A5: Type | B5: Reading (m) | C5: Reduced level | D5: Elevation (m above base station) | E5: Orthometric height (m) | F5: Environment/Notes | H5: Indicative range
A6: BS to St 1 | B6: 2.26 | F6: Halimeda mud/mudflat | H6: peat-forming mangrove
A7: FS to St 2 | B7: 2.1 | C7: =B$6-B7 -> 0.16 | D7: =C7-C$34 -> -0.545 | E7: =D7+M$2 -> -0.38813 | F7: On Rhizo root mat (maybe not peat forming), edge of fringe
A8: FS to St 3 | B8: 1.86 | C8: =B$6-B8 -> 0.4 | D8: =C8-C$34 -> -0.305 | E8: =D8+M$2 -> -0.14813 | F8: "" into fringe, leaves and organics, probably peat-forming edge | H8: =MIN(E8:E14,E35:E36,E40,E16,E18:E22,E24:E27,E37) -> -0.14813 | I8: min
A9: FS to St 4 | B9: 1.74 | C9: =B$6-B9 -> 0.52 | D9: =C9-C$34 -> -0.185 | E9: =D9+M$2 -> -0.02813 | F9: peat-forming Rhizo fringe (canopy ~5 m) | H9: =MAX(E8:E14,E35:E36,E40,E16,E18:E22,E24:E27,E37) -> 0.32187 | I9: max
A10: FS to St 5 | B10: 1.55 | C10: =B$6-B10 -> 0.71 | D10: =C10-C$34 -> 0.005 | E10: =D10+M$2 -> 0.16187 | F10: ""
A11: FS to St 6 | B11: 1.535 | C11: =B$6-B11 -> 0.725 | D11: =C11-C$34 -> 0.02 | E11: =D11+M$2 -> 0.17687 | F11: ""
A12: FS to St 7 | B12: 1.51 | C12: =B$6-B12 -> 0.75 | D12: =C12-C$34 -> 0.045 | E12: =D12+M$2 -> 0.20187 | F12: "" | H12: {=E8:E14} -> -0.14813
A13: FS to St 8 | B13: 1.49 | C13: =B$6-B13 -> 0.77 | D13: =C13-C$34 -> 0.065 | E13: =D13+M$2 -> 0.22187 | F13: "" | H13: -0.02813
A14: FS to St 9 | B14: 1.495 | C14: =B$6-B14 -> 0.765 | D14: =C14-C$34 -> 0.06 | E14: =D14+M$2 -> 0.21687 | F14: "" at boundary with scrub dieback | H14: 0.16187
A15: BS to St 9 | B15: 1.16 | H15: 0.17687
A16: FS to St 10 | B16: 1.17 | C16: =B15-B16+C14 -> 0.755 | D16: =C16-C$34 -> 0.05 | E16: =D16+M$2 -> 0.20687 | F16: fully into scrub/basin dwarf (canopy ~2 m) | H16: 0.20187
A17: BS to St 10 | B17: 1.715 | H17: 0.22187
A18: FS to St 11 | B18: 1.73 | C18: =B$17-B18+C$16 -> 0.74 | D18: =C18-C$34 -> 0.035 | E18: =D18+M$2 -> 0.19187 | F18: "" | H18: 0.21687
A19: FS to St 12 | B19: 1.725 | C19: =B$17-B19+C$16 -> 0.745 | D19: =C19-C$34 -> 0.04 | E19: =D19+M$2 -> 0.19687 | F19: "" | H19: =E16 -> 0.20687
A20: FS to St 13 | B20: 1.725 | C20: =B$17-B20+C$16 -> 0.745 | D20: =C20-C$34 -> 0.04 | E20: =D20+M$2 -> 0.19687 | F20: "" | H20: {=E18:E22} -> 0.19187
A21: FS to St 14 | B21: 1.76 | C21: =B$17-B21+C$16 -> 0.71 | D21: =C21-C$34 -> 0.005 | E21: =D21+M$2 -> 0.16187 | F21: "" | H21: 0.19687
A22: FS to St 15 | B22: 1.66 | C22: =B$17-B22+C$16 -> 0.81 | D22: =C22-C$34 -> 0.105 | E22: =D22+M$2 -> 0.26187 | F22: "" | H22: 0.19687
A23: BS to St 15 | B23: 1.7 | H23: 0.16187
A24: FS to St 16 | B24: 1.68 | C24: =B$23-B24+C$22 -> 0.83 | D24: =C24-C$34 -> 0.125 | E24: =D24+M$2 -> 0.28187 | F24: into transition to area with tall (~3 m) Rhizo | H24: 0.26187
A25: FS to St 17 | B25: 1.64 | C25: =B$23-B25+C$22 -> 0.87 | D25: =C25-C$34 -> 0.165 | E25: =D25+M$2 -> 0.32187 | F25: fully into tall Rhizo | H25: {=E24:E27} -> 0.28187
A26: FS to St 18 | B26: 1.66 | C26: =B$23-B26+C$22 -> 0.85 | D26: =C26-C$34 -> 0.145 | E26: =D26+M$2 -> 0.30187 | F26: "" | H26: 0.32187
A27: FS to St 19 | B27: 1.71 | C27: =B$23-B27+C$22 -> 0.8 | D27: =C27-C$34 -> 0.095 | E27: =D27+M$2 -> 0.25187 | F27: on boundary with depression/zone of peat collapse | H27: 0.30187
A28: BS to St 19 | B28: 1.515 | H28: 0.25187
A29: FS to edge of flooded dwarf | B29: 2.12 | C29: =B$28-B29+C$27 -> 0.195 | D29: =C29-C$34 -> -0.51 | E29: =D29+M$2 -> -0.35313 | H29: {=E35:E37} -> 0.20687
A30: FS to flooded dwarf 1 | B30: 2.475 | C30: =B$28-B30+C$27 -> -0.16 | D30: =C30-C$34 -> -0.865 | E30: =D30+M$2 -> -0.70813 | H30: 0.24187
A31: FS to flooded dwarf 2 | B31: 1.93 | C31: =B$28-B31+C$27 -> 0.385 | D31: =C31-C$34 -> -0.32 | E31: =D31+M$2 -> -0.16313 | H31: 0.25687
A32: FS to flooded dwarf 3 | B32: 1.75 | C32: =B$28-B32+C$27 -> 0.565 | D32: =C32-C$34 -> -0.14 | E32: =D32+M$2 -> 0.01687 | H32: =E40 -> 0.25187
A33: FS to other edge of flooded dwarf | B33: 1.73 | C33: =B$28-B33+C$27 -> 0.585 | D33: =C33-C$34 -> -0.12 | E33: =D33+M$2 -> 0.03687
A34: FS to base station | B34: 1.61 | C34: =B$28-B34+C$27 -> 0.705 | D34: =C34-C$34 -> 0 | E34: =D34+M$2 -> 0.15687 | F34: TWIN BASE
A35: FS to St 20 | B35: 1.56 | C35: =B$28-B35+C$27 -> 0.755 | D35: =C35-C$34 -> 0.05 | E35: =D35+M$2 -> 0.20687 | F35: into peat-forming dwarf
A36: FS to St 21 | B36: 1.525 | C36: =B$28-B36+C$27 -> 0.79 | D36: =C36-C$34 -> 0.085 | E36: =D36+M$2 -> 0.24187 | F36: peat-forming dwarf
A37: FS to t 22 | B37: 1.51 | C37: =B$28-B37+C$27 -> 0.805 | D37: =C37-C$34 -> 0.1 | E37: =D37+M$2 -> 0.25687 | F37: in transition to fringe (still dwarf)
A38: BS to St 22 | B38: 1.415
A39: FS to GR/19/C1 | B39: 1.385 | C39: =B$38-B39+C$37 -> 0.835 | D39: =C39-C$34 -> 0.13 | E39: =D39+M$2 -> 0.28687
A40: FS to St 23 | B40: 1.42 | C40: =B$38-B40+C$37 -> 0.8 | D40: =C40-C$34 -> 0.095 | E40: =D40+M$2 -> 0.25187 | F40: fully into channel-side Rhizo fringe (peat-forming)
A41: FS to top of WL logger | B41: 1.81 | C41: =B$38-B41+C$37 -> 0.41 | D41: =C41-C$34 -> -0.295 | E41: =D41+M$2 -> -0.13813
...

Sheet Oscar
A1: Site: | B1: OS/19 | N1: OS as TBM | O1: Ellipsoid height | P1: Geoid Height | Q1: Orthometric height | T1: OS C2 | U1: Ellipsoid height | V1: Geoid Height | W1: Orthometric height | Z1: TWIN Base as TBM | AA1: Ellipsoid height | AB1: Geoid Height | AC1: Orthometric height
A2: Date: | B2: 43804 | O2: -4.35345 | P2: -4.61655 | Q2: =O2-P2 -> 0.2631 | U2: -4.49206 | V2: -4.61245 | W2: =U2-V2 -> 0.12039 | AA2: -4.462 | AB2: -4.61887 | AC2: 0.15687
A3: What: | B3: Leveling OS environmental zones and strat transect
A5: Type | B5: Reading (m) | C5: Reduced level | D5: Elevation (m TBM) | E5: Orthometric elevation (m) | F5: Environment/Notes | L5: Indicative range | O5: Elevation (m C2) | P5: Orthometric elevation (m) | Q5: Elevation (m TBM) where TBM is TWINBase | R5: Orthometric elevation (m) | S5: diff OS &C2 | T5: diff TWINBase & C2
A6: BS to St 1 | B6: 2.39 | F6: below mangrove platform edge, organic rich carbonate mud | L6: peat-forming mangrove
A7: FS to St 2 | B7: 1.68 | C7: =B$6-B7 -> 0.71 | D7: =C7-C$12 -> -0.13 | E7: =D7+Q$2 -> 0.1331 | F7: into red mangrove fringe on platform, peat-forming mangrove | O7: =C7-C$24 -> -0.08 | P7: =O7+W$2 -> 0.04039 | Q7: =C7-C$12 -> -0.13 | R7: =Q7+AC$2 -> 0.02687 | S7: =E7-P7 -> 0.09271 | T7: =R7-P7 -> -0.01352
A8: FS to St 3 | B8: 1.525 | C8: =B$6-B8 -> 0.865 | D8: =C8-C$12 -> 0.025 | E8: =D8+Q$2 -> 0.2881 | F8: same as last, in dense roots at channel fringe (4 m canopy) | L8: =MIN(E$7:E$11,E$31,E$35,E$38,E$40:E$41,E$46,E$48:E$50,E33,E45) -> 0.1331 | M8: min | O8: =C8-C$24 -> 0.075 | P8: =O8+W$2 -> 0.19539 | Q8: =C8-C$12 -> 0.025 | R8: =Q8+AC$2 -> 0.18187 | S8: =E8-P8 -> 0.09271 | T8: =R8-P8 -> -0.01352
A9: FS to St 4 | B9: 1.5 | C9: =B$6-B9 -> 0.89 | D9: =C9-C$12 -> 0.05 | E9: =D9+Q$2 -> 0.3131 | F9: transition to scrub dieback, canopy 2-3 m, peat forming | L9: =MAX(E$7:E$11,E$31,E$35,E$38,E$40:E$41,E$46,E$48:E$50,E33,E45) -> 0.4531 | M9: max | O9: =C9-C$24 -> 0.1 | P9: =O9+W$2 -> 0.22039 | Q9: =C9-C$12 -> 0.05 | R9: =Q9+AC$2 -> 0.20687 | S9: =E9-P9 -> 0.09271 | T9: =R9-P9 -> -0.01352
A10: FS to St 5 | B10: 1.51 | C10: =B$6-B10 -> 0.88 | D10: =C10-C$12 -> 0.04 | E10: =D10+Q$2 -> 0.3031 | F10: same as last, canopy 1-2 m | O10: =C10-C$24 -> 0.09 | P10: =O10+W$2 -> 0.21039 | Q10: =C10-C$12 -> 0.04 | R10: =Q10+AC$2 -> 0.19687 | S10: =E10-P10 -> 0.09271 | T10: =R10-P10 -> -0.01352
A11: FS to St 6 | B11: 1.51 | C11: =B$6-B11 -> 0.88 | D11: =C11-C$12 -> 0.04 | E11: =D11+Q$2 -> 0.3031 | F11: fully into dwarf zone, peat forming | L11: =E7 -> 0.1331 | O11: =C11-C$24 -> 0.09 | P11: =O11+W$2 -> 0.21039 | Q11: =C11-C$12 -> 0.04 | R11: =Q11+AC$2 -> 0.19687 | S11: =E11-P11 -> 0.09271 | T11: =R11-P11 -> -0.01352
A12: FS to TBM | B12: 1.55 | C12: =B$6-B12 -> 0.84 | D12: =C12-C$12 -> 0 | E12: =D12+Q$2 -> 0.2631 | F12: Tanghua to set up RTK Rover here | I12: TBM refers to OS on RTK sheet | L12: =E8 -> 0.2881 | O12: =C12-C$24 -> 0.05 | P12: =O12+W$2 -> 0.17039 | Q12: =C12-C$12 -> 0 | R12: =Q12+AC$2 -> 0.15687 | S12: =E12-P12 -> 0.09271 | T12: =R12-P12 -> -0.01352
A13: BS to TBM | B13: 1.45 | L13: =E9 -> 0.3131
A14: FS to C1 | B14: 1.47 | C14: =B$13-B14+C$12 -> 0.82 | D14: =C14-C$12 -> -0.02 | E14: =D14+Q$2 -> 0.2431 | L14: =E10 -> 0.3031 | O14: =C14-C$24 -> 0.03 | P14: =O14+W$2 -> 0.15039 | Q14: =C14-C$12 -> -0.02 | R14: =Q14+AC$2 -> 0.13687 | S14: =E14-P14 -> 0.09271 | T14: =R14-P14 -> -0.01352
A15: FS to St 7 | B15: 1.42 | C15: =B$13-B15+C$12 -> 0.87 | D15: =C15-C$12 -> 0.03 | E15: =D15+Q$2 -> 0.2931 | F15: "" | L15: =E11 -> 0.3031 | O15: =C15-C$24 -> 0.08 | P15: =O15+W$2 -> 0.20039 | Q15: =C15-C$12 -> 0.03 | R15: =Q15+AC$2 -> 0.18687 | S15: =E15-P15 -> 0.09271 | T15: =R15-P15 -> -0.01352
A16: FS to St 8 | B16: 1.52 | C16: =B$13-B16+C$12 -> 0.77 | D16: =C16-C$12 -> -0.07 | E16: =D16+Q$2 -> 0.1931 | F16: getting into flooded dwarf zone with jelly fish | L16: =E15 -> 0.2931 | O16: =C16-C$24 -> -0.02 | P16: =O16+W$2 -> 0.10039 | Q16: =C16-C$12 -> -0.07 | R16: =Q16+AC$2 -> 0.08687 | S16: =E16-P16 -> 0.09271 | T16: =R16-P16 -> -0.01352
A17: FS to St 9 | B17: 1.57 | C17: =B$13-B17+C$12 -> 0.72 | D17: =C17-C$12 -> -0.12 | E17: =D17+Q$2 -> 0.1431 | F17: "" | L17: =E31 -> 0.4531 | O17: =C17-C$24 -> -0.07 | P17: =O17+W$2 -> 0.05039 | Q17: =C17-C$12 -> -0.12 | R17: =Q17+AC$2 -> 0.03687 | S17: =E17-P17 -> 0.09271 | T17: =R17-P17 -> -0.01352
A18: FS to St 10 | B18: 1.61 | C18: =B$13-B18+C$12 -> 0.68 | D18: =C18-C$12 -> -0.16 | E18: =D18+Q$2 -> 0.1031 | F18: "" | L18: =E33 -> 0.4231 | O18: =C18-C$24 -> -0.11 | P18: =O18+W$2 -> 0.01039 | Q18: =C18-C$12 -> -0.16 | R18: =Q18+AC$2 -> -0.00313 | S18: =E18-P18 -> 0.09271 | T18: =R18-P18 -> -0.01352
A19: FS to St 11 | B19: 1.6 | C19: =B$13-B19+C$12 -> 0.69 | D19: =C19-C$12 -> -0.15 | E19: =D19+Q$2 -> 0.1131 | F19: "" | L19: =E35 -> 0.4081 | O19: =C19-C$24 -> -0.1 | P19: =O19+W$2 -> 0.02039 | Q19: =C19-C$12 -> -0.15 | R19: =Q19+AC$2 -> 0.00687 | S19: =E19-P19 -> 0.09271 | T19: =R19-P19 -> -0.01352
A20: FS to St 12 | B20: 1.44 | C20: =B$13-B20+C$12 -> 0.85 | D20: =C20-C$12 -> 0.01 | E20: =D20+Q$2 -> 0.2731 | F20: into denser, firmer ground | L20: =E38 -> 0.3881 | O20: =C20-C$24 -> 0.06 | P20: =O20+W$2 -> 0.18039 | Q20: =C20-C$12 -> 0.01 | R20: =Q20+AC$2 -> 0.16687 | S20: =E20-P20 -> 0.09271 | T20: =R20-P20 -> -0.01352
A21: FS to St 13 | B21: 1.46 | C21: =B$13-B21+C$12 -> 0.83 | D21: =C21-C$12 -> -0.01 | E21: =D21+Q$2 -> 0.2531 | F21: "" | L21: =E40 -> 0.4031 | O21: =C21-C$24 -> 0.04 | P21: =O21+W$2 -> 0.16039 | Q21: =C21-C$12 -> -0.01 | R21: =Q21+AC$2 -> 0.14687 | S21: =E21-P21 -> 0.09271 | T21: =R21-P21 -> -0.01352
A22: FS to St 14 | B22: 1.46 | C22: =B$13-B22+C$12 -> 0.83 | D22: =C22-C$12 -> -0.01 | E22: =D22+Q$2 -> 0.2531 | F22: "" | L22: =E41 -> 0.4131 | O22: =C22-C$24 -> 0.04 | P22: =O22+W$2 -> 0.16039 | Q22: =C22-C$12 -> -0.01 | R22: =Q22+AC$2 -> 0.14687 | S22: =E22-P22 -> 0.09271 | T22: =R22-P22 -> -0.01352
A23: FS to St 15 | B23: 1.47 | C23: =B$13-B23+C$12 -> 0.82 | D23: =C23-C$12 -> -0.02 | E23: =D23+Q$2 -> 0.2431 | F23: "" | L23: =E45 -> 0.4231 | O23: =C23-C$24 -> 0.03 | P23: =O23+W$2 -> 0.15039 | Q23: =C23-C$12 -> -0.02 | R23: =Q23+AC$2 -> 0.13687 | S23: =E23-P23 -> 0.09271 | T23: =R23-P23 -> -0.01352
A24: FS to C2 | B24: 1.5 | C24: =B$13-B24+C$12 -> 0.79 | D24: =C24-C$12 -> -0.05 | E24: =D24+Q$2 -> 0.2131 | L24: =E46 -> 0.4131 | O24: =C24-C$24 -> 0 | P24: =O24+W$2 -> 0.12039 | Q24: =C24-C$12 -> -0.05 | R24: =Q24+AC$2 -> 0.10687 | S24: =E24-P24 -> 0.09271 | T24: =R24-P24 -> -0.01352
A25: FS to St 16 | B25: 1.48 | C25: =B$13-B25+C$12 -> 0.81 | D25: =C25-C$12 -> -0.03 | E25: =D25+Q$2 -> 0.2331 | F25: "" | L25: =E48 -> 0.3681 | O25: =C25-C$24 -> 0.02 | P25: =O25+W$2 -> 0.14039 | Q25: =C25-C$12 -> -0.03 | R25: =Q25+AC$2 -> 0.12687 | S25: =E25-P25 -> 0.09271 | T25: =R25-P25 -> -0.01352
A26: FS | B26: 1.68 | C26: =B$13-B26+C$12 -> 0.61 | D26: =C26-C$12 -> -0.23 | E26: =D26+Q$2 -> 0.0331 | F26: no sample, into deeper water near pond | L26: =E49 -> 0.3431 | O26: =C26-C$24 -> -0.18 | P26: =O26+W$2 -> -0.05961 | Q26: =C26-C$12 -> -0.23 | R26: =Q26+AC$2 -> -0.07313 | S26: =E26-P26 -> 0.09271 | T26: =R26-P26 -> -0.01352
A27: FS to St 17 | B27: 1.67 | C27: =B$13-B27+C$12 -> 0.62 | D27: =C27-C$12 -> -0.22 | E27: =D27+Q$2 -> 0.0431 | L27: =E50 -> 0.2981 | O27: =C27-C$24 -> -0.17 | P27: =O27+W$2 -> -0.04961 | Q27: =C27-C$12 -> -0.22 | R27: =Q27+AC$2 -> -0.06313 | S27: =E27-P27 -> 0.09271 | T27: =R27-P27 -> -0.01352
A28: FS | B28: 1.7 | C28: =B$13-B28+C$12 -> 0.59 | D28: =C28-C$12 -> -0.25 | E28: =D28+Q$2 -> 0.0131 | O28: =C28-C$24 -> -0.2 | P28: =O28+W$2 -> -0.07961 | Q28: =C28-C$12 -> -0.25 | R28: =Q28+AC$2 -> -0.09313 | S28: =E28-P28 -> 0.09271 | T28: =R28-P28 -> -0.01352
A29: BS | B29: 1.96
A30: FS to St 18 | B30: 1.625 | C30: =B$29-B30+C$28 -> 0.925 | D30: =C30-C$12 -> 0.085 | E30: =D30+Q$2 -> 0.3481 | F30: height of nconsolidated algal/microbial mat surface in open pond (exposed at low tide) | O30: =C30-C$24 -> 0.135 | P30: =O30+W$2 -> 0.25539 | Q30: =C30-C$12 -> 0.085 | R30: =Q30+AC$2 -> 0.24187 | S30: =E30-P30 -> 0.09271 | T30: =R30-P30 -> -0.01352
A31: FS to St 19 | B31: 1.52 | C31: =B$29-B31+C$28 -> 1.03 | D31: =C31-C$12 -> 0.19 | E31: =D31+Q$2 -> 0.4531 | F31: into peat forming env again, red, black, and white mangroves in basin zone | O31: =C31-C$24 -> 0.24 | P31: =O31+W$2 -> 0.36039 | Q31: =C31-C$12 -> 0.19 | R31: =Q31+AC$2 -> 0.34687 | S31: =E31-P31 -> 0.09271 | T31: =R31-P31 -> -0.01352
A32: BS to St 19 | B32: 1.335
A33: FS to St 20 | B33: 1.365 | C33: =B32-B33+C31 -> 1 | D33: =C33-C$12 -> 0.16 | E33: =D33+Q$2 -> 0.4231 | F33: further into basin with big black trees | O33: =C33-C$24 -> 0.21 | P33: =O33+W$2 -> 0.33039 | Q33: =C33-C$12 -> 0.16 | R33: =Q33+AC$2 -> 0.31687 | S33: =E33-P33 -> 0.09271 | T33: =R33-P33 -> -0.01352
A34: BS to St 20 | B34: 1.6 | O34: =C34-C$24 -> -0.79 | P34: =O34+W$2 -> -0.66961 | Q34: =C34-C$12 -> -0.84 | R34: =Q34+AC$2 -> -0.68313 | S34: =E34-P34 -> 0.66961 | T34: =R34-P34 -> -0.01352
A35: FS to St 21 | B35: 1.615 | C35: =B34-B35+C33 -> 0.985 | D35: =C35-C$12 -> 0.145 | E35: =D35+Q$2 -> 0.4081 | F35: big blacks and ~-m reds, peat forming | O35: =C35-C$24 -> 0.195 | P35: =O35+W$2 -> 0.31539 | Q35: =C35-C$12 -> 0.145 | R35: =Q35+AC$2 -> 0.30187 | S35: =E35-P35 -> 0.09271 | T35: =R35-P35 -> -0.01352
A36: BS to St 21 | B36: 1.55
A37: FS to C3 | B37: 1.56 | C37: =B36-B37+C35 -> 0.975 | D37: =C37-C$12 -> 0.135 | E37: =D37+Q$2 -> 0.3981 | O37: =C37-C$24 -> 0.185 | P37: =O37+W$2 -> 0.30539 | Q37: =C37-C$12 -> 0.135 | R37: =Q37+AC$2 -> 0.29187 | S37: =E37-P37 -> 0.09271 | T37: =R37-P37 -> -0.01352
A38: FS to St 22 | B38: 1.57 | C38: =B36-B38+C35 -> 0.965 | D38: =C38-C$12 -> 0.125 | E38: =D38+Q$2 -> 0.3881 | F38: same as last, fewer blacks | O38: =C38-C$24 -> 0.175 | P38: =O38+W$2 -> 0.29539 | Q38: =C38-C$12 -> 0.125 | R38: =Q38+AC$2 -> 0.28187 | S38: =E38-P38 -> 0.09271 | T38: =R38-P38 -> -0.01352
A39: BS to St 22 | B39: 1.66
A40: FS to St 23 | B40: 1.645 | C40: =B39-B40+C38 -> 0.98 | D40: =C40-C$12 -> 0.14 | E40: =D40+Q$2 -> 0.4031 | F40: still in basin, Rhizo canopy ~ 1 m, few blacks | O40: =C40-C$24 -> 0.19 | P40: =O40+W$2 -> 0.31039 | Q40: =C40-C$12 -> 0.14 | R40: =Q40+AC$2 -> 0.29687 | S40: =E40-P40 -> 0.09271 | T40: =R40-P40 -> -0.01352
A41: FS to St 24 | B41: 1.635 | C41: =B39-B41+C38 -> 0.99 | D41: =C41-C$12 -> 0.15 | E41: =D41+Q$2 -> 0.4131 | F41: same as last | O41: =C41-C$24 -> 0.2 | P41: =O41+W$2 -> 0.32039 | Q41: =C41-C$12 -> 0.15 | R41: =Q41+AC$2 -> 0.30687 | S41: =E41-P41 -> 0.09271 | T41: =R41-P41 -> -0.01352
...

Sheet BertErnie
A1: Site: | B1: BE/19 | F1: Note: core 4 was not levelled to in the modern transect, although there was an RTK point | I1: TWINBase TBM | J1: Ellipsoid height | K1: Geoid Height | L1: Orthometric height | O1: BE Rover | P1: Ellipsoid height | Q1: Geoid Height | R1: Orthometric height
A2: Date: | B2: 5/14/19-5/15/19 | J2: -4.462 | K2: -4.61887 | L2: 0.15687 | P2: -4.42305 | Q2: -4.6291 | R2: 0.20605
A3: What: | B3: Leveling BE environmental zones and strat transect | F3: check indicative meanings again with Nicole!
A5: Type | B5: Reading (m) | C5: Reduced level | D5: Elevation (m above Rover) | E5: Orthometric height (m) | F5: Environment/Notes | G5: Indicative range
A6: BS to St 1 | B6: 2.1 | F6: Just outside of fringe near entrace to channel, substrate fine carbonate sand with detrital organics | G6: peat forming mangrove
A7: FS to St 2 | B7: 1.86 | C7: =B$6-B7 -> 0.24 | D7: =C7-C$32 -> -0.24 | E7: =D7+R$2 -> -0.03395 | F7: Substrate same as last, moved into edge of red fringe
A8: FS to St 3 | B8: 1.59 | C8: =B$6-B8 -> 0.51 | D8: =C8-C$32 -> 0.03 | E8: =D8+R$2 -> 0.23605 | F8: substrate dense root mat withh sand and algae accumulating at surface
A9: FS to St 4 | B9: 1.49 | C9: =B$6-B9 -> 0.61 | D9: =C9-C$32 -> 0.13 | E9: =D9+R$2 -> 0.33605 | F9: substrate same as last (more sandy)
A10: FS to St 5 | B10: 1.47 | C10: =B$6-B10 -> 0.63 | D10: =C10-C$32 -> 0.15 | E10: =D10+R$2 -> 0.35605 | F10: substrate sandy peat with algal mat
A11: FS to St 6 | B11: 1.47 | C11: =B$6-B11 -> 0.63 | D11: =C11-C$32 -> 0.15 | E11: =D11+R$2 -> 0.35605 | F11: same as St 5 with more organic debris (leaves, bark) accummulating at surface | G11: =MIN(E12,E13,E16:E20,E22:E23,E25:E30) -> 0.21605 | H11: min
A12: FS to St 7 | B12: 1.44 | C12: =B$6-B12 -> 0.66 | D12: =C12-C$32 -> 0.18 | E12: =D12+R$2 -> 0.38605 | F12: boundary between fringe and basin, substrate - peat accumulating with leaves and organic matter, no mat | G12: =MAX(E12:E13,E16:E20,E22:E23,E25:E30) -> 0.51605 | H12: max
A13: FS to St 8 | B13: 1.31 | C13: =B$6-B13 -> 0.79 | D13: =C13-C$32 -> 0.31 | E13: =D13+R$2 -> 0.51605 | F13: mixed species basin, thick accumulations of organic matter, sea grass and algae washed in with leaves, no root mat
A14: FS to TBM | B14: 1.14 | C14: =B$6-B14 -> 0.96 | D14: =C14-C$32 -> 0.48 | E14: =D14+R$2 -> 0.68605 | F14: end of day, set up TBM. Does not refer to TWINBase; temporary benchmark set up to tie one survey to the survey on the next day, but orthometric height not measured at this location | G14: =E12 -> 0.38605
A15: BS to TBM | B15: 1.25 | G15: =E13 -> 0.51605
A16: FS to St 9 | B16: 1.45 | C16: =B$15-B16+C$14 -> 0.76 | D16: =C16-C$32 -> 0.28 | E16: =D16+R$2 -> 0.48605 | F16: stations up to this point have been spaced ~3 apart, n mixed species basin, sampled collected near white and black pneumatophores, substrate same as st 8 | G16: =E16 -> 0.48605
A17: FS to St 10 | B17: 1.46 | C17: =B$15-B17+C$14 -> 0.75 | D17: =C17-C$32 -> 0.27 | E17: =D17+R$2 -> 0.47605 | F17: less thick pile of organic matter, was 10-15 cm at 8 and 9, now ~ 5 cm, Rhizo dominated | G17: =E17 -> 0.47605
A18: FS to St 11 | B18: 1.45 | C18: =B$15-B18+C$14 -> 0.76 | D18: =C18-C$32 -> 0.28 | E18: =D18+R$2 -> 0.48605 | F18: same as St 10 with some black and white pneumos | G18: =E18 -> 0.48605
A19: FS to St 12 | B19: 1.46 | C19: =B$15-B19+C$14 -> 0.75 | D19: =C19-C$32 -> 0.27 | E19: =D19+R$2 -> 0.47605 | F19: same as St 11, transitioning to lower Rhizo canopy and higher blacks (4 m) | G19: =E19 -> 0.47605
A20: FS to St 13 | B20: 1.47 | C20: =B$15-B20+C$14 -> 0.74 | D20: =C20-C$32 -> 0.26 | E20: =D20+R$2 -> 0.46605 | F20: denser 4-5 m black mangroves and 2-3 Rhizos, humic accumulation thinner ~0-2 cm | G20: =E20 -> 0.46605
A21: BS to St 13 | B21: 1.47 | G21: =E22 -> 0.43605
A22: FS to St 14 | B22: 1.5 | C22: =B$21-B22+C$20 -> 0.71 | D22: =C22-C$32 -> 0.23 | E22: =D22+R$2 -> 0.43605 | F22: same depositional env as St 13 with fewer black trees | G22: =E23 -> 0.42605
A23: FS to St 15 | B23: 1.51 | C23: =B$21-B23+C$20 -> 0.7 | D23: =C23-C$32 -> 0.22 | E23: =D23+R$2 -> 0.42605 | F23: transitioned from mixed species to all Rhizos - canopy ~ 2 m | G23: =E25 -> 0.42105
A24: BS to St 15 | B24: 1.53 | G24: =E26 -> 0.36605
A25: FS to St 16 | B25: 1.535 | C25: =B$24-B25+C$23 -> 0.695 | D25: =C25-C$32 -> 0.215 | E25: =D25+R$2 -> 0.42105 | F25: substrate dense root mat with 1-2 mm of humic organic material at surface | G25: =E27 -> 0.33605
A26: FS to St 17 | B26: 1.59 | C26: =B$24-B26+C$23 -> 0.64 | D26: =C26-C$32 -> 0.16 | E26: =D26+R$2 -> 0.36605 | F26: less dense dwarf Rhizo basin, thick dense root mat as substrate | G26: =E28 -> 0.30605
A27: FS to St 18 | B27: 1.62 | C27: =B$24-B27+C$23 -> 0.61 | D27: =C27-C$32 -> 0.13 | E27: =D27+R$2 -> 0.33605 | F27: same as St 17 | G27: =E29 -> 0.25605
A28: FS to St 19 | B28: 1.65 | C28: =B$24-B28+C$23 -> 0.58 | D28: =C28-C$32 -> 0.1 | E28: =D28+R$2 -> 0.30605 | F28: "" | G28: =E30 -> 0.21605
A29: FS to St 20 | B29: 1.7 | C29: =B$24-B29+C$23 -> 0.53 | D29: =C29-C$32 -> 0.05 | E29: =D29+R$2 -> 0.25605 | F29: ""
A30: FS to St 21 | B30: 1.74 | C30: =B$24-B30+C$23 -> 0.49 | D30: =C30-C$32 -> 0.01 | E30: =D30+R$2 -> 0.21605 | F30: ""
A31: FS to BE/19/C1 | B31: 1.78 | C31: =B$24-B31+C$23 -> 0.45 | D31: =C31-C$32 -> -0.03 | E31: =D31+R$2 -> 0.17605
A32: FS to ROVER | B32: 1.75 | C32: =B$24-B32+C$23 -> 0.48 | D32: =C32-C$32 -> 0 | E32: =D32+R$2 -> 0.20605 | F32: BE Rover (RTK point)
A33: BS to ROVER | B33: 1.68 | D33: =C33-C$32 -> -0.48
A34: FS to BE/19/C2 | B34: 1.65 | C34: =B$33-B34+C$32 -> 0.51 | D34: =C34-C$32 -> 0.03 | E34: =D34+R$2 -> 0.23605
A35: FS to BE/19/C3 | B35: 1.48 | C35: =B$33-B35+C$32 -> 0.68 | D35: =C35-C$32 -> 0.2 | E35: =D35+R$2 -> 0.40605
A37: Checking levels
A38: BS | B38: =SUM(B6,B15,B21,B24,B33) -> 8.03
A39: FS | B39: =SUM(B14,B20,B23,B32,B35) -> 7.35
A40: Difference | B40: =B38-B39 -> 0.68

Sheet BigBird (Fangyi)
A1: Site: | B1: BB/19 | N1: BB Rover | O1: Ellipsoid height | P1: Geoid Height | Q1: Orthometric height
A2: Date: | B2: 43603 | O2: -4.42867 | P2: -4.59775 | Q2: =O2-P2 -> 0.16908
A3: What: | B3: Leveling and sampling modern transect
A5: Type | B5: Reading (m) | C5: Reduced level | D5: Elevation (m above Rover) | E5: Orthometric height (m) | F5: Environment/Notes | L5: Indicative range
A6: BS to St 1 | B6: 2.16 | F6: Dense algal layer over rooted surface, sea grass and organics just beyond fringe in channel
A7: FS to St 2 | B7: 1.84 | C7: =B$6-B7 -> 0.32 | D7: =C7-C$25 -> -0.055 | E7: =D7+Q$2 -> 0.11408 | F7: same as st. 1
A8: FS to St 3 | B8: 1.67 | C8: =B$6-B8 -> 0.49 | D8: =C8-C$25 -> 0.115 | E8: =D8+Q$2 -> 0.28408 | F8: into peat-forming boundary (bottom edge) in red fringe | L8: =MIN(E$8:E$13,E$31,E$16:E$18,E$20:E$21,E$38:E$39,E$41:E$43,E$45:E$48) -> 0.21908 | M8: min
A9: FS to St 4 | B9: 1.6 | C9: =B$6-B9 -> 0.56 | D9: =C9-C$25 -> 0.185 | E9: =D9+Q$2 -> 0.35408 | L9: =MAX(E$8:E$13,E$31,E$16:E$18,E$20:E$21,E$38:E$39,E$41:E$43,E$45:E$48) -> 0.49908 | M9: max
A10: FS to St 5 | B10: 1.58 | C10: =B$6-B10 -> 0.58 | D10: =C10-C$25 -> 0.205 | E10: =D10+Q$2 -> 0.37408
A11: FS to St 6 | B11: 1.53 | C11: =B$6-B11 -> 0.63 | D11: =C11-C$25 -> 0.255 | E11: =D11+Q$2 -> 0.42408 | F11: accumulation of leaf litter and sea grass at surface; black and white pneumos | L11: =E8 -> 0.28408
A12: FS to St 7 | B12: 1.49 | C12: =B$6-B12 -> 0.67 | D12: =C12-C$25 -> 0.295 | E12: =D12+Q$2 -> 0.46408 | L12: =E9 -> 0.35408
A13: FS to St 8 | B13: 1.49 | C13: =B$6-B13 -> 0.67 | D13: =C13-C$25 -> 0.295 | E13: =D13+Q$2 -> 0.46408 | F13: at back end of fringe; black and white pneumos present | L13: =E10 -> 0.37408
A14: FS to St 9 | B14: 1.505 | C14: =B$6-B14 -> 0.655 | D14: =C14-C$25 -> 0.28 | E14: =D14+Q$2 -> 0.44908 | F14: transition into dwarf basin; less dense root mat than in fringe | L14: =E11 -> 0.42408
A15: BS to St 9 | B15: 1.4 | L15: =E12 -> 0.46408
A16: FS to St 10 | B16: 1.405 | C16: =B$15-B16+C$14 -> 0.65 | D16: =C16-C$25 -> 0.275 | E16: =D16+Q$2 -> 0.44408 | F16: same as st 9 | L16: =E13 -> 0.46408
A17: FS to St 11 | B17: 1.4 | C17: =B$15-B17+C$14 -> 0.655 | D17: =C17-C$25 -> 0.28 | E17: =D17+Q$2 -> 0.44908 | F17: transition entering dwarf basin; substrate same as st 9; black pneumos but all Rhizo trees at ~2 m | L17: =E16 -> 0.44408
A18: FS to St 12 | B18: 1.42 | C18: =B$15-B18+C$14 -> 0.635 | D18: =C18-C$25 -> 0.26 | E18: =D18+Q$2 -> 0.42908 | L18: =E17 -> 0.44908
A19: BS to St 12 | B19: 1.66 | L19: =E18 -> 0.42908
A20: FS to St 13 | B20: 1.69 | C20: =B$19-B20+C$18 -> 0.605 | D20: =C20-C$25 -> 0.23 | E20: =D20+Q$2 -> 0.39908 | L20: =E20 -> 0.39908
A21: FS to St 14 | B21: 1.7 | C21: =B$19-B21+C$18 -> 0.595 | D21: =C21-C$25 -> 0.22 | E21: =D21+Q$2 -> 0.38908 | F21: into dwarf basin; denser root mat than st 13 | L21: =E21 -> 0.38908
A22: FS to St 15 | B22: 1.87 | C22: =B$19-B22+C$18 -> 0.425 | D22: =C22-C$25 -> 0.05 | E22: =D22+Q$2 -> 0.21908 | F22: into sparse dwarf pond | L22: =E31 -> 0.35908
A23: FS to St 16 | B23: 1.91 | C23: =B$19-B23+C$18 -> 0.385 | D23: =C23-C$25 -> 0.01 | E23: =D23+Q$2 -> 0.17908 | F23: "" | L23: =E38 -> 0.44908
A24: BS to St 16 | B24: 1.58 | L24: =E39 -> 0.46908
A25: FS to Rover | B25: 1.59 | C25: =B$24-B25+C$23 -> 0.375 | D25: =C25-C$25 -> 0 | E25: =D25+Q$2 -> 0.16908 | F25: "" | L25: =E41 -> 0.49908
A26: FS to St 17 | B26: 1.63 | C26: =B$24-B26+C$23 -> 0.335 | D26: =C26-C$25 -> -0.04 | E26: =D26+Q$2 -> 0.12908 | F26: "" | L26: =E42 -> 0.40908
A27: FS to St 18 | B27: 1.58 | C27: =B$24-B27+C$23 -> 0.385 | D27: =C27-C$25 -> 0.01 | E27: =D27+Q$2 -> 0.17908 | F27: all in dwarf pond zone | L27: =E43 -> 0.39908
A28: FS to open pond | B28: 1.59 | C28: =B$24-B28+C$23 -> 0.375 | D28: =C28-C$25 -> 0 | E28: =D28+Q$2 -> 0.16908 | L28: =E45 -> 0.38908
A29: FS to St 19 | B29: 1.53 | C29: =B$24-B29+C$23 -> 0.435 | D29: =C29-C$25 -> 0.06 | E29: =D29+Q$2 -> 0.22908 | F29: open pond | L29: =E46 -> 0.34908
A30: BS to St 19 | B30: 1.45 | L30: =E47 -> 0.29908
A31: FS to St 20 | B31: 1.32 | C31: =B$30-B31+C$29 -> 0.565 | D31: =C31-C$25 -> 0.19 | E31: =D31+Q$2 -> 0.35908 | F31: 100% Rhizo basin ~2m; rooted peat and thin layer of mangrove detritis | L31: =E48 -> 0.21908
A32: FS to St 21 | B32: 1.29 | C32: =B$30-B32+C$29 -> 0.595 | D32: =C32-C$25 -> 0.22 | E32: =D32+Q$2 -> 0.38908
A33: FS to Rhizo basin | B33: 1.29 | C33: =B$30-B33+C$29 -> 0.595 | D33: =C33-C$25 -> 0.22 | E33: =D33+Q$2 -> 0.38908
A34: BS to Rhizo basin | B34: 1.4
A35: FS to St 22 | B35: 1.39 | C35: =B$34-B35+C$33 -> 0.605 | D35: =C35-C$25 -> 0.23 | E35: =D35+Q$2 -> 0.39908
A36: FS to St 23 | B36: 1.37 | C36: =B$34-B36+C$33 -> 0.625 | D36: =C36-C$25 -> 0.25 | E36: =D36+Q$2 -> 0.41908
A37: BS to St 23 | B37: 1.43
A38: FS to St 24 | B38: 1.4 | C38: =B$37-B38+C$36 -> 0.655 | D38: =C38-C$25 -> 0.28 | E38: =D38+Q$2 -> 0.44908 | F38: mixed species basin, black ~4 m Rhizo, Rhizo ~3m and turtle grass
A39: FS to mixed basin | B39: 1.38 | C39: =B$37-B39+C$36 -> 0.675 | D39: =C39-C$25 -> 0.3 | E39: =D39+Q$2 -> 0.46908
A40: BS to mixed basin | B40: 1.43
A41: FS to St 25 | B41: 1.4 | C41: =B$40-B41+C$39 -> 0.705 | D41: =C41-C$25 -> 0.33 | E41: =D41+Q$2 -> 0.49908 | F41: same as station 24 but no turtle grass
...

Sheet BigBird (Nicole)
A1: Site: | B1: BB/19
A2: Date: | B2: 43603
A3: What: | B3: Leveling and sampling modern transect | G3: NK calculated
A5: Type | B5: Reading (m) | C5: Reduced level | D5: Environment/Notes
A6: BS to St 1 | B6: 2.16 | C6: =B$6-B7 -> 0.32 | D6: Dense algal layer over rooted surface, sea grass and organics just beyond fringe in channel
A7: FS to St 2 | B7: 1.84 | C7: =B$6-B8 -> 0.49 | D7: same as st. 1
A8: FS to St 3 | B8: 1.67 | C8: =B$6-B9 -> 0.56 | D8: into peat-forming boundary (bottom edge) in red fringe
A9: FS to St 4 | B9: 1.6 | C9: =B$6-B10 -> 0.58
A10: FS to St 5 | B10: 1.58 | C10: =B$6-B11 -> 0.63
A11: FS to St 6 | B11: 1.53 | C11: =B$6-B12 -> 0.67 | D11: accumulation of leaf litter and sea grass at surface; black and white pneumos
A12: FS to St 7 | B12: 1.49 | C12: =B$6-B13 -> 0.67
A13: FS to St 8 | B13: 1.49 | C13: =B$6-B14 -> 0.655 | D13: at back end of fringe; black and white pneumos present
A14: FS to St 9 | B14: 1.505 | C14: =B$6-B15 -> 0.76 | D14: transition into dwarf basin; less dense root mat than in fringe
A15: BS to St 9 | B15: 1.4
A16: FS to St 10 | B16: 1.405 | C16: =B$15-B16+C$14 -> 0.755 | D16: same as st 9
A17: FS to St 11 | B17: 1.4 | C17: =B$15-B17+C$14 -> 0.76 | D17: transition entering dwarf basin; substrate same as st 9; black pneumos but all Rhizo trees at ~2 m
A18: FS to St 12 | B18: 1.42 | C18: =B$15-B18+C$14 -> 0.74
A19: BS to St 12 | B19: 1.66
A20: FS to St 13 | B20: 1.69 | C20: =B$20-B21+C$18 -> 0.73
A21: FS to St 14 | B21: 1.7 | C21: =B$20-B22+C$18 -> 0.56 | D21: into dwarf basin; denser root mat than st 13
A22: FS to St 15 | B22: 1.87 | C22: =B$20-B23+C$18 -> 0.52 | D22: into sparse dwarf pond
A23: FS to St 16 | B23: 1.91 | C23: =B$20-B24+C$18 -> 0.85 | D23: ""
A24: BS to St 16 | B24: 1.58
A25: FS to Rover | B25: 1.59 | C25: =B$24-B25+C$23 -> 0.84 | D25: ""
A26: FS to St 17 | B26: 1.63 | C26: =B$24-B26+C$23 -> 0.8 | D26: ""
A27: FS to St 18 | B27: 1.58 | C27: =B$24-B27+C$23 -> 0.85 | D27: all in dwarf pond zone
A28: FS to open pond | B28: 1.59 | C28: =B$24-B28+C$23 -> 0.84
A29: FS to St 19 | B29: 1.53 | C29: =B$24-B29+C$23 -> 0.9 | D29: open pond
A30: BS to St 19 | B30: 1.45
A31: FS to St 20 | B31: 1.32 | C31: =B$30-B31+C$29 -> 1.03 | D31: 100% Rhizo basin ~2m; rooted peat and thin layer of mangrove detritis
A32: FS to St 21 | B32: 1.29 | C32: =B$30-B32+C$29 -> 1.06
A33: FS to Rhizo basin | B33: 1.29 | C33: =B$30-B33+C$29 -> 1.06
A34: BS to Rhizo basin | B34: 1.4
A35: FS to St 22 | B35: 1.39 | C35: =B$34-B35+C$33 -> 1.07
A36: FS to St 23 | B36: 1.37 | C36: =B$34-B36+C$33 -> 1.09
A37: BS to St 23 | B37: 1.43
A38: FS to St 24 | B38: 1.4 | C38: =B$37-B38+C$36 -> 1.12 | D38: mixed species basin, black ~4 m Rhizo, Rhizo ~3m and turtle grass
A39: FS to mixed basin | B39: 1.38 | C39: =B$37-B39+C$36 -> 1.14
A40: BS to mixed basin | B40: 1.43
A41: FS to St 25 | B41: 1.4 | C41: =B$40-B41+C$39 -> 1.17 | D41: same as station 24 but no turtle grass
...

Sheet CookieMonster
A1: Site: | B1: CM/19 | J1: TFY Calculated | O1: CM Rover | P1: Ellipsoid height | Q1: Geoid Height | R1: Orthometric height
A2: Date: | B2: 43604 | P2: -4.57181 | Q2: -4.63752 | R2: =P2-Q2 -> 0.06571
A3: What: | B3: Leveling modern transect and environmental zones
A5: Type | B5: Reading | C5: Reduced level | D5: Elevation (m above Rover) | E5: Orthometric height (m) | F5: Notes | N5: Indicative meaning
A6: BS to Rover | B6: 1.83 | C6: 0 | N6: peat-forming mangrove
A7: FS to St 1 | B7: 1.825 | C7: =B$6-B7 -> 0.005 | D7: =C7-C$6 -> 0.005 | E7: =D7+R$2 -> 0.07071 | F7: In open pond
A8: FS to St 2 | B8: 1.71 | C8: =B$6-B8 -> 0.12 | D8: =C8-C$6 -> 0.12 | E8: =D8+R$2 -> 0.18571 | F8: In dwarf fringing pond, red algal mat on top of leaf layer, root mat (not so dense) below
A9: FS to St 3 | B9: 1.595 | C9: =B$6-B9 -> 0.235 | D9: =C9-C$6 -> 0.235 | E9: =D9+R$2 -> 0.30071 | F9: In the middle of inundated dwarf zone, still thick algal mat and leaf litter, starting to see balck pneumos
A10: FS to St 4 | B10: 1.5 | C10: =B$6-B10 -> 0.33 | D10: =C10-C$6 -> 0.33 | E10: =D10+R$2 -> 0.39571
A11: BS to St 4 | B11: 1.68 | N11: =MIN(E$12:E$14,E$16:E$20) -> 0.39071 | O11: min
A12: FS to St 5 | B12: 1.635 | C12: =B$11-B12+C$10 -> 0.375 | D12: =C12-C$6 -> 0.375 | E12: =D12+R$2 -> 0.44071 | F12: Into back of monospecific black zone, think layer of green algae on peat surface (first peat-forming station) | N12: =MAX(E$12:E$14,E$16:E$20) -> 0.50571 | O12: max
A13: FS to St 6 | B13: 1.63 | C13: =B$11-B13+C$10 -> 0.38 | D13: =C13-C$6 -> 0.38 | E13: =D13+R$2 -> 0.44571 | F13: Into black zone, some Batis present nearby
A14: FS to St 7 | B14: 1.63 | C14: =B$11-B14+C$10 -> 0.38 | D14: =C14-C$6 -> 0.38 | E14: =D14+R$2 -> 0.44571 | F14: "" but no Batis | N14: {=E12:E14} -> 0.44071
A15: BS to St 7 | B15: 1.475 | N15: 0.44571
A16: FS to St 8 | B16: 1.48 | C16: =B$15-B16+C$14 -> 0.375 | D16: =C16-C$6 -> 0.375 | E16: =D16+R$2 -> 0.44071 | F16: "" | N16: 0.44571
A17: FS to St 9 | B17: 1.46 | C17: =B$15-B17+C$14 -> 0.395 | D17: =C17-C$6 -> 0.395 | E17: =D17+R$2 -> 0.46071 | F17: In transition from black basin to Rhizo fringe | N17: {=E16:E20} -> 0.44071
A18: FS to St 10 | B18: 1.415 | C18: =B$15-B18+C$14 -> 0.44 | D18: =C18-C$6 -> 0.44 | E18: =D18+R$2 -> 0.50571 | F18: In transition (on Rhizo side), still black pneumos, lots of trash accumulation here | N18: 0.46071
A19: FS to St 11 | B19: 1.455 | C19: =B$15-B19+C$14 -> 0.4 | D19: =C19-C$6 -> 0.4 | E19: =D19+R$2 -> 0.46571 | F19: In fringe, in area of high tide accumulation | N19: 0.50571
A20: FS to St 12 | B20: 1.53 | C20: =B$15-B20+C$14 -> 0.325 | D20: =C20-C$6 -> 0.325 | E20: =D20+R$2 -> 0.39071 | F20: In dense root mat | N20: 0.46571
A21: FS to St 13 | B21: 1.58 | C21: =B$15-B21+C$14 -> 0.275 | D21: =C21-C$6 -> 0.275 | E21: =D21+R$2 -> 0.34071 | F21: "" green algae on mat | N21: 0.39071
A22: FS to St 14 | B22: 1.77 | C22: =B$15-B22+C$14 -> 0.085 | D22: =C22-C$6 -> 0.085 | E22: =D22+R$2 -> 0.15071 | F22: root mat with carbonate sand on surface (seagrass groawing nearby)
A23: FS to St 15 | B23: 2.02 | C23: =B$15-B23+C$14 -> -0.165 | D23: =C23-C$6 -> -0.165 | E23: =D23+R$2 -> -0.09929 | F23: Just in Rhizo platform undercut near root, where wave-cut/under carbonate sand mat
A24: FS to St 16 | B24: 2.12 | C24: =B$15-B24+C$14 -> -0.265 | D24: =C24-C$6 -> -0.265 | E24: =D24+R$2 -> -0.19929
B26: Checking levels
B27: BS | C27: =SUM(B6,B11,B15) -> 4.985
B28: FS | C28: =SUM(B10,B14,B24) -> 5.25
B29: Difference | C29: =C27-C28 -> -0.265

Sheet Stratigraphy
A1: Oscar transect
A2: TS, JM, TL
A3: 5/13/19
L4: 0 | M4: 0
A5: Core 1 | B5: 16.83099 | C5: -88.10534 | L5: 12 | M5: 0
A6: Depth (cm) | B6: Description
A7: 0-972 | B7: Red mangrove peat
A8: 972-990 | B8: transition to intertidal mud
A9: 990-1000 | B9: intertidal mud
A11: Core 2 | B11: 16.83033 | C11: -88.1059
A12: Depth (cm) | B12: Description
A13: 0-725 | B13: Red mangrove peat
A14: 725-767 | B14: Muddy mangrove peat
A15: 767-844 | B15: intertidal mud
A16: 844 | B16: bedrock
A18: Core 3 | B18: 16.8296 | C18: -88.10652
A19: Depth (cm) | B19: Description
A20: 0-972 | B20: Mangrove peat
A21: 972-1003 | B21: transition to intertidal mud
A22: 1003-1100 | B22: intertidal mud
A23: 1100 | B23: bedrock
A25: Core 4 | B25: 16.8292 | C25: -88.10688
A26: Depth (cm) | B26: Description
A27: 0-430 | B27: Mangrove peat
A28: 430-510 | B28: Shelly sandy mud with fine roots
A29: 510-970 | B29: mangrove peat with 1-2 cm layers of shelly sandy mud at 515, 530, and 550 | C29: *impenetrable object (wood?) at 670, started new core
A30: 970-1133 | B30: muddy brown peat
A31: 1133-1300 | B31: grey mud
A32: 1300- | B32: couldn't penetrate further, mud very stiff
A35: Bert and Ernie transect
A36: TS, JM, TL
A37: 5/14/19
A39: Core 1 | B39: 16.83366 | C39: -88.10463
A40: Depth (cm) | B40: Description
A41: 0-1117 | B41: Mangrove peat
A42: 1117-1127 | B42: transition to intertidal mud
A43: 1127-1137 | B43: weathered bedrock (limestone)
A45: Core 2 | B45: 16.83419 | C45: -88.1049
A46: Depth (cm) | B46: Description
A47: 0-1113 | B47: Mangrove peat
...

Sheet BrainCores
A1: PLANNED
A2: Environment | B2: Sample ID | C2: Replicates
A3: Channel bottom | B3: Near GR/19 boat landing | C3: 1
A4: Seagrass bed | B4: Platform on channel cut or bed on backside (open coast side) of Oscar transect | C4: 1
A5: Fringe Rhizophora | B5: GR/19 fringe, OS/19/St 27 or 28 | C5: 2
A6: Scrub basin | B6: GR/19/St 11 | C6: 1
A7: Dwarf basin
A8: 'firm' | B8: GR/19/St 20, BE/19/St 18 | C8: 2
A9: 'collapsing' | B9: GR/19/landward of St 19, OS/19/St 10 or 17 | C9: 2
A10: Mixed species basin | B10: BE/19/St 8, OS/19/St 19 or 20 | C10: 2
C11: =SUM(C3:C10) -> 11
A12: ACTUAL
A13: Sample ID | B13: Nearest station | C13: Environment
A14: GR/19/AC1 | B14: GR/19/C1 | C14: Rhizophora fringe
A15: GR/19/AC2 | B15: next to RTK base/rover | C15: Dwarf Rhizophora
A16: GR/19/AC3 | B16: GR/19/St11 | C16: Rhizophora scrub basin
A17: GR/19/AC4 | B17: GR/19/St19 | C17: collapsing' dwarf Rhizophora
A18: BE/19/AC5 | B18: BE/19/St18 | C18: Dwarf Rhizophora
A19: BE/19/AC6 | B19: BE/19/St12 | C19: Mixed species basin
A20: CM/19/AC7 | B20: CM/19/St8 | C20: Monospecific Avicennia basin
A21: OS/19/AC8 | B21: ~80 cm water depth @ 3 pm | C21: Seagrass bed
A22: OS/19/AC9 | B22: OS/19/St26 | C22: Rhizophora fringe
A23: OS/19/AC10 | B23: OS/19/C3 | C23: Mixed species basin
A24: OS/19/AC11 | B24: OS/19/St17 | C24: collapsing' dwarf Rhizophora
A25: GR/19/AC12 | B25: in channel near water logger | C25: Channel bottom

Sheet RTKLog
A1: Base | C1: Rover
A2: Date | B2: Location | C2: Date | D2: Location
A3: 43595 | B3: Carrie Bow Cay | C3: 43595 | D3: GR/19
A4: 43596 | B4: GR/19
A5: 43597 | B5: GR/19
A6: 43598 | B6: GR/19 | C6: 43598 | D6: OS/19
A7: 43599 | B7: GR/19 | C7: 43599 | D7: BE/19
A8: 43600 | B8: GR/19 | C8: 43600 | D8: BE/19
A9: 43601 | B9: GR/19
A10: 43602 | B10: GR/19
A11: 43603 | B11: GR/19 | C11: 43603 | D11: BB/19
A12: 43604 | B12: GR/19 | C12: 43604 | D12: CM/19
A13: 43605 | B13: GR/19 | C13: 43605 | D13: OS/19/C2
A14: 43606 | B14: GR/19 | C14: 43606 | D14: BE/19/C4, CBC/19 benchmark and logger
A15: 43606 | B15: CBC/10 benchmark | C15: 43606 | D15: Carrie Bow Cay

Sheet Radiocarbon
A1: 5/19/19
A2: Picking radiocarbon dates
A3: NK and KJ
A5: Sample Depth (cm) | B5: Description
A6: 1147 | B6: piece of wood (doesn't appear to be red mangrove wood), photos on NK phone | L6: =1200/75 -> 16
A7: 1090 | B7: pieces of red mangrove leaves and prop root (separate vials), leaves not cleaned (don't have the correct tools)
A8: 834 | B8: pieces of mangrove wood and prop bark (separate vials)
A12: 9/17/19
A13: Picking radiocarbon dates
A14: NK and TFY
J15: Samples not sending for dating
A16: Sample depth | B16: Samples Description | C16: Dry wt (mg) | D16: Notes | J16: Depth | K16: Type | L16: Weight (mg)
A17: 1145-1146 | B17: Mangrove wood | C17: 5 | D17: Small piece of wood (twig?) at edge of peat substrate. Questioned if in situ, but deemed fine as cores have undergone significant transport from Belize to NJ to SG | J17: 937-938 cm | K17: Prop roots | L17: 41
A18: 1046-1047 | B18: Mangrove wood | C18: 32 | D18: 1-cm piece of mangrove wood
A19: 1078-1079 | B19: Mangrove wood | C19: 11 | D19: Small piece of wood in middle of layer
A20: 1002-1003 | B20: Mangrove wood | C20: 37 | D20: Small piece of wood in middle of layer
A21: 937-938 | B21: MANGROVE WOOD | C21: 41 | D21: Large piece of wood from surface. Few pieces of prop root but did not date -- kept in separate valve.
A22: 870-871 | B22: Mangrove wood | C22: 33 | D22: Small wood 'nub' at surface of core
A23: 766-768 | B23: Mangrove wood | D23: Large piece of wood from surface (very spongy)
A24: 643-644 | B24: Mangrove wood
A25: 596-595 | B25: Mangrove wood | D25: Small (<0.3 cm) pieces of wood at surface (more in center of core)
A26: 552-553 | B26: Mangrove wood | D26: Large (~1 cm) wood chunk at surface
A27: 481-482 | B27: mangrove wood | D27: Small piece of wood under surface layer
A28: 406.5-407.5 | B28: mangrove wood | D28: small piece of wood (twig) from surface
A29: 361-362 | B29: mangrove wood | D29: small piece of wood found under surface layer
A30: 256-257 | B30: Mangrove wood | D30: Small piece of wood at surface
A31: 201-202 | B31: mangrove wood | D31: Small piece of wood fragments at surface (maybe not in situ)
A32: 144-145 | B32: mangrove wood | D32: small piece of wood (twig and nub) in surface layer
A33: 160-161 | B33: mangrove wood | D33: large piece of woody bark below surface layer
A34: 76-77 | B34: mangrove wood | D34: very small piece at edge of core (maybe not in situ)
A35: 24-25 | B35: mangrove wood
A40: 44278
A41: Fine fraction filtration
A42: TFY and GR
A44: Core | B44: Sample depth | C44: Filter ID | D44: Sample ID | E44: Baked filter weight (g) | F44: Dry weight filter and sample (g) | G44: Sample weight (F-E) (mg) | H44: Comments
E45: prior to filtration | F45: after filtration
A46: GR/19/C1 REP B 840-490 | B46: 850-851 | C46: 1 | D46: GR/19/C1/B/850-851/A | E46: 0.1528 | F46: 0.1693 | G46: =(F46-E46)*1000 -> 16.5 | H46: Peat
A47: GR/19/C1 REP B 840-490 | B47: 850-851 | C47: 2 | D47: GR/19/C1/B/850-851/B | E47: 0.1501 | F47: 0.1676 | G47: =(F47-E47)*1000 -> 17.5
A48: GR/19/C1 REP B 840-490 | B48: 850-851 | C48: 3 | D48: GR/19/C1/B/850-851/C | E48: 0.1504 | F48: 0.1686 | G48: =(F48-E48)*1000 -> 18.2
A49: GR/19/C1 REP B 800-850 | B49: 844-845 | C49: 4 | D49: GR/19/C1/B/844-845/A | E49: 0.154 | F49: 0.163 | G49: =(F49-E49)*1000 -> 9 | H49: Peat; large soft macro picked out after sieving (bark?)
...

Sheet 2021 Dating plan
A1: 44216 | B1: Yen, Fangyi, Sarah checked cores in Fridge
A2: Log of cores in fridge
A3: Oscar (OS) | B3: Grover (GR) Rep C | D3: Grover (GR) Rep A | F3: Grover (GR) Rep B
A4: OS/19/C2 000-050 | B4: A core | C4: B Core | D4: A core | E4: B core | F4: A core | G4: B Core
A5: OS/19/C2 050-100 | B5: GR/19/C1 Rep C 0000-0050 | C5: GR/19/C1 Rep C 0040-0090 | D5: GR/19/C1 Rep A 0000-0050 | E5: GR/19/C1 Rep A 0040-0090 | F5: GR/19/C1 Rep B 0000-0050 | G5: GR/19/C1 Rep B 0040-0090
A6: OS/19/C2 100-150 | B6: GR/19/C1 Rep C 0080-0130 | C6: GR/19/C1 Rep C 0120-0170 | D6: GR/19/C1 Rep A 0080-0130 | E6: GR/19/C1 Rep A 0120-0170 | F6: GR/19/C1 Rep B 80-130 | G6: GR/19/C1 Rep B 0120-0170
A7: OS/19/C2 150-200 | B7: GR/19/C1 Rep C 0160-0210 | C7: GR/19/C1 Rep C 0200-0250 | D7: GR/19/C1 Rep A 0160-0210 | E7: GR/19/C1 Rep A 0200-0250 | F7: GR/19/C1 Rep B 0160-0210 | G7: GR/19/C1 Rep B 0200-0250
A8: OS/19/C2 200-250 | B8: GR/19/C1 Rep C 0240-0290 | C8: GR/19/C1 Rep C 0280-0330 | D8: GR/19/C1 Rep A 0240-0290 | E8: GR/19/C1 Rep A 0280-0330 | F8: GR/19/C1 Rep B 0240-0290 | G8: GR/19/C1 Rep B 280-330
A9: OS/19/C2 250-300 | B9: GR/19/C1 Rep C 0320-0370 | C9: GR/19/C1 Rep C 0360-0410 | D9: GR/19/C1 Rep A 0320-0370 | E9: GR/19/C1 Rep A 0360-0410 | F9: GR/19/C1 Rep B 0320-0370 | G9: GR/19/C1 Rep B 0360-0410
A10: OS/19/C2 300-350 | B10: GR/19/C1 Rep C 0400-0450 | C10: GR/19/C1 Rep C 0440-0490 | D10: GR/19/C1 Rep A 0400-0450 | E10: GR/19/C1 Rep A 0440-0490 | F10: GR/19/C1 Rep B 0400-0450 | G10: GR/19/C1 Rep B 0440-0490
A11: OS/19/C2 350-400 | B11: GR/19/C1 Rep C 0480-0530 | C11: GR/19/C1 Rep C 0520-0570 | D11: GR/19/C1 Rep A 0480-0530 | E11: GR/19/C1 Rep A 0520-0570 | F11: GR/19/C1 Rep B 480-530 | G11: GR/19/C1 Rep B 0520-0570
A12: OS/19/C2 400-450 | B12: GR/19/C1 Rep C 0560-0610 | C12: GR/19/C1 Rep C 0600-0650 | D12: GR/19/C1 Rep A 0560-0610 | E12: GR/19/C1 Rep A 0600-0650 | F12: GR/19/C1 Rep B 0560-0610 | G12: GR/19/C1 Rep B 0600-0650
A13: OS/19/C2 450-500 | B13: GR/19/C1 Rep C 0640-0690 | C13: GR/19/C1 Rep C 0680-0730 | D13: GR/19/C1 Rep A 0640-0690 | E13: GR/19/C1 Rep A 0680-0730 | F13: GR/19/C1 Rep B 0640-0690 | G13: GR/19/C1 Rep B 680-730
A14: OS/19/C2 500-550 | B14: GR/19/C1 Rep C 0720-0770 | C14: GR/19/C1 Rep C 0760-0810 | D14: GR/19/C1 Rep A 0720-0770 | E14: GR/19/C1 Rep A 0760-0810 | F14: GR/19/C1 Rep B 0720-0770 | G14: GR/19/C1 Rep B 0760-0810
A15: OS/19/C2 550-600 | B15: GR/19/C1 Rep C 0800-0850 | C15: GR/19/C1 Rep C 0840-0890 | D15: GR/19/C1 Rep A 0800-0850 | E15: GR/19/C1 Rep A 0840-0890 | F15: GR/19/C1 Rep B 0800-0850 | G15: GR/19/C1 Rep B 0840-0890
... A18: OS/19/C2 700-750 | B18: GR/19/C1 Rep C 1040-1090 | C18: GR/19/C1 Rep C 1080-1130 | D18: GR/19/C1 Rep A 1040-1090 | E18: GR/19/C1 Rep A 1080-1130 | F18: GR/19/C1 Rep B 1040-1090 | G18: GR/19/C1 Rep B 1080-1130
A19: OS/19/C2 750-800 | B19: GR/19/C1 Rep C 1120-1170 | C19: GR/19/C1 Rep C 1160-1210 | D19: GR/19/C1 Rep A 1120-1170 | E19: GR/19/C1 Rep A 1160-1210 | F19: GR/19/C1 Rep B 1120-1170
A20: OS/19/C2 759-809 | B20: GR/19/C1 Rep C A hole 1156-1206
F21: bolded were shipped back from Rutgers
F22: Sections to date
A25: Plan for dating (GR/19/C1 Rep B)
A26: Depth | B26: Core A | C26: Core B | E26: picked dates from these in 2019
A27: 644 - 870 | B27: GR/19/C1 Rep B 0640-0690 | C27: GR/19/C1 Rep B 0680-0730
B28: GR/19/C1 Rep B 0720-0770 | C28: GR/19/C1 Rep B 0760-0810
B29: GR/19/C1 Rep B 0800-0850 | C29: GR/19/C1 Rep B 0840-0890
A30: 482-595 | B30: GR/19/C1 Rep B 0560-0610 | C30: GR/19/C1 Rep B 0440-0490
B31: GR/19/C1 Rep B 0480-0530 | C31: GR/19/C1 Rep B 0520-0570
A32: 257-361 | B32: GR/19/C1 Rep B 0240-0290 | C32: GR/19/C1 Rep B 280-330
B33: GR/19/C1 Rep B 0320-0370
A34: 25-141 | B34: GR/19/C1 Rep B 0000-0050 | C34: GR/19/C1 Rep B 0040-0090
B35: GR/19/C1 Rep B 0080-0130 | C35: GR/19/C1 Rep B 0120-0170

Sheet RSL SLIPs
A1: From 'results/Belize SLIPs.csv' in 'Belize Plots 'RProject
A2: Last updated: | B2: 44307
A4: sampleID | B4: sample depth (m) | C4: sample thickness uncertainty (m) | D4: type | E4: year_sampled | F4: sample elevation (m msl) | G4: Age (cal. yrs BP) | H4: Age upper 2sd (cal. yrs BP) | I4: Age lower 2sd (cal. yrs BP) | J4: MLW (m msl) | K4: MHW (m msl) | L4: MTL (m msl) | M4: HAT (m msl) | N4: LAT (m msl) | O4: MHHW (m msl) | P4: MLHW (m msl) | Q4: MHLW (m msl) | R4: MLLW (m msl) | S4: MSL (m msl) | T4: RSL (m) | U4: RSL upper (m) | V4: RSL lower (m)
A5: Beta 538705 | B5: 0.24 | C5: 0.005 | D5: full modern IM | E5: 2019 | F5: -0.4565763 | G5: 131 | H5: 10 | I5: 271 | J5: -0.0653 | K5: 0.0698 | L5: 0.0023 | M5: 0.1431 | N5: -0.1829 | O5: 0.0767 | P5: 0.0628 | Q5: -0.0313 | R5: -0.0988 | S5: 0 | T5: -0.39151571 | U5: 0.098610498 | V5: -0.88164192
A6: Beta 538707 | B6: 0.76 | C6: 0.005 | D6: full modern IM | E6: 2019 | F6: -0.9765763 | G6: 7056 | H6: 6954 | I6: 7158 | J6: -0.0653 | K6: 0.0698 | L6: 0.0023 | M6: 0.1431 | N6: -0.1829 | O6: 0.0767 | P6: 0.0628 | Q6: -0.0313 | R6: -0.0988 | S6: 0 | T6: -0.91151571 | U6: -0.4213895 | V6: -1.4016419
A7: Beta 538706 | B7: 1.44 | C7: 0.005 | D7: full modern IM | E7: 2019 | F7: -1.6565763 | G7: 3343 | H7: 3247 | I7: 3445 | J7: -0.0653 | K7: 0.0698 | L7: 0.0023 | M7: 0.1431 | N7: -0.1829 | O7: 0.0767 | P7: 0.0628 | Q7: -0.0313 | R7: -0.0988 | S7: 0 | T7: -1.5915157 | U7: -1.1013895 | V7: -2.0816419
A8: Beta 538704 | B8: 1.6 | C8: 0.005 | D8: full modern IM | E8: 2019 | F8: -1.8165763 | G8: 3762 | H8: 3648 | I8: 3841 | J8: -0.0653 | K8: 0.0698 | L8: 0.0023 | M8: 0.1431 | N8: -0.1829 | O8: 0.0767 | P8: 0.0628 | Q8: -0.0313 | R8: -0.0988 | S8: 0 | T8: -1.7515157 | U8: -1.2613895 | V8: -2.2416419
A9: Beta 538722 | B9: 1.96 | C9: 0.005 | D9: full modern IM | E9: 2019 | F9: -2.1765763 | G9: 4019 | H9: 3910 | I9: 4141 | J9: -0.0653 | K9: 0.0698 | L9: 0.0023 | M9: 0.1431 | N9: -0.1829 | O9: 0.0767 | P9: 0.0628 | Q9: -0.0313 | R9: -0.0988 | S9: 0 | T9: -2.1115157 | U9: -1.6213895 | V9: -2.6016419
A10: Beta 538709 | B10: 2.56 | C10: 0.005 | D10: full modern IM | E10: 2019 | F10: -2.7765763 | G10: 4138 | H10: 3996 | I10: 4240 | J10: -0.0653 | K10: 0.0698 | L10: 0.0023 | M10: 0.1431 | N10: -0.1829 | O10: 0.0767 | P10: 0.0628 | Q10: -0.0313 | R10: -0.0988 | S10: 0 | T10: -2.7115157 | U10: -2.2213895 | V10: -3.2016419
A11: Beta 538714 | B11: 3.61 | C11: 0.01 | D11: full modern IM | E11: 2019 | F11: -3.8315763 | G11: 5397 | H11: 5319 | I11: 5468 | J11: -0.0653 | K11: 0.0698 | L11: 0.0023 | M11: 0.1431 | N11: -0.1829 | O11: 0.0767 | P11: 0.0628 | Q11: -0.0313 | R11: -0.0988 | S11: 0 | T11: -3.7665157 | U11: -3.2713895 | V11: -4.2616419
A12: Beta 538710 | B12: 4.065 | C12: 0.005 | D12: full modern IM | E12: 2019 | F12: -4.2815763 | G12: 5643 | H12: 5591 | I12: 5718 | J12: -0.0653 | K12: 0.0698 | L12: 0.0023 | M12: 0.1431 | N12: -0.1829 | O12: 0.0767 | P12: 0.0628 | Q12: -0.0313 | R12: -0.0988 | S12: 0 | T12: -4.2165157 | U12: -3.7263895 | V12: -4.7066419
A13: Beta 538708 | B13: 4.81 | C13: 0.005 | D13: full modern IM | E13: 2019 | F13: -5.0265763 | G13: 5737 | H13: 5604 | I13: 5892 | J13: -0.0653 | K13: 0.0698 | L13: 0.0023 | M13: 0.1431 | N13: -0.1829 | O13: 0.0767 | P13: 0.0628 | Q13: -0.0313 | R13: -0.0988 | S13: 0 | T13: -4.9615157 | U13: -4.4713895 | V13: -5.4516419
A14: Beta 538712 | B14: 5.52 | C14: 0.005 | D14: full modern IM | E14: 2019 | F14: -5.7365763 | G14: 6896 | H14: 6795 | I14: 6985 | J14: -0.0653 | K14: 0.0698 | L14: 0.0023 | M14: 0.1431 | N14: -0.1829 | O14: 0.0767 | P14: 0.0628 | Q14: -0.0313 | R14: -0.0988 | S14: 0 | T14: -5.6715157 | U14: -5.1813895 | V14: -6.1616419
A15: Beta 538716 | B15: 5.95 | C15: 0.005 | D15: full modern IM | E15: 2019 | F15: -6.1665763 | G15: 6638 | H15: 6508 | I15: 6739 | J15: -0.0653 | K15: 0.0698 | L15: 0.0023 | M15: 0.1431 | N15: -0.1829 | O15: 0.0767 | P15: 0.0628 | Q15: -0.0313 | R15: -0.0988 | S15: 0 | T15: -6.1015157 | U15: -5.6113895 | V15: -6.5916419
A16: Beta 538718 | B16: 6.43 | C16: 0.005 | D16: full modern IM | E16: 2019 | F16: -6.6465763 | G16: 7047 | H16: 6946 | I16: 7159 | J16: -0.0653 | K16: 0.0698 | L16: 0.0023 | M16: 0.1431 | N16: -0.1829 | O16: 0.0767 | P16: 0.0628 | Q16: -0.0313 | R16: -0.0988 | S16: 0 | T16: -6.5815157 | U16: -6.0913895 | V16: -7.0716419
... A29: Beta 588802 | B29: 8.505 | C29: 0.005 | D29: full modern IM | E29: 2021 | F29: -8.7215763 | G29: 7069 | H29: 6964 | I29: 7163 | J29: -0.0653 | K29: 0.0698 | L29: 0.0023 | M29: 0.1431 | N29: -0.1829 | O29: 0.0767 | P29: 0.0628 | Q29: -0.0313 | R29: -0.0988 | S29: 0 | T29: -8.6565157 | U29: -8.1663895 | V29: -9.1466419
